Workbook

Sheet 0. Parametri
A1: Parametri Cost Model — Input Centralizzato
A2: Verde=dato certo da gara/RAI | Giallo=assunzione operativa cost modeler | Rosso=bloccante irrisolto (valore default per far girare il modello)
A3: Testo blu = input modificabile dal cost modeler. Nessuna cella in questo sheet contiene formule.
A5: # | B5: Categoria | C5: Parametro | D5: Valore | E5: Unità | F5: Fonte / Origine | G5: Note
A6: 1. ECONOMICS DI GARA — Valori contrattuali (€)
A7: 1 | B7: Valore Appalto | C7: Startup / affiancamento (3 mesi) — non ribassabile | E7: €
A8: 2 | B8: Valore Appalto | C8: Canone presidio 36 mesi — soggetto a ribasso | E8: €
A9: 3 | B9: Valore Appalto | C9: Plafond T&M 36 mesi — non vincolante per RAI | E9: €
A10: 4 | B10: Valore Appalto | C10: Canone proroga 24 mesi — soggetto a ribasso | E10: €
A11: 5 | B11: Valore Appalto | C11: Plafond T&M proroga 24 mesi | E11: €
A12: 6 | B12: Valore Appalto | C12: Oneri sicurezza | E12: €
A13: 2. TARIFFE T&M — Base d'asta (Disciplinare p.13)
A14: 7 | B14: Tariffe T&M | C14: Tariffa Architetto Applicativo | E14: €/GG
A15: 8 | B15: Tariffe T&M | C15: Tariffa TL/Analista funzionale | E15: €/GG
A16: 9 | B16: Tariffe T&M | C16: Tariffa Analista Programmatore | E16: €/GG
A17: 10 | B17: Tariffe T&M | C17: Tariffa Programmatore | E17: €/GG
A18: 3. VOLUMI T&M — Capitolato p.36 (scelta S1: BLOCCANTE non risolto, adottato Capitolato)
A19: 11 | B19: Volumi T&M | C19: Architetto Applicativo — GG/U/anno | E19: GG/U/anno
A20: 12 | B20: Volumi T&M | C20: TL/Analista funzionale — GG/U/anno | E20: GG/U/anno
A21: 13 | B21: Volumi T&M | C21: Analista Programmatore — GG/U/anno | E21: GG/U/anno
A22: 14 | B22: Volumi T&M | C22: Programmatore — GG/U/anno | E22: GG/U/anno
A23: 4. COMPOSIZIONE TEAM CANONE — N. risorse (Capitolato pp.13-14,34)
A24: 15 | B24: Team Canone | C24: Service Manager / PM | E24: n
A25: 16 | B25: Team Canone | C25: Team Leader d'area (BE+FE+Mob+TV) | E25: n
A26: 17 | B26: Team Canone | C26: Technical Leader (totale 4 aree) | E26: n
A27: 18 | B27: Team Canone | C27: Analista Programmatore (totale) | E27: n
A28: 19 | B28: Team Canone | C28: Programmatore (totale) | E28: n
A29: 5. COSTI INTERNI — Costo giornaliero pieno aziendale (€/GG)
A30: 20 | B30: Costo Interno | C30: Service Manager / PM | E30: €/GG
A31: 21 | B31: Costo Interno | C31: Team Leader d'area | E31: €/GG
A32: 22 | B32: Costo Interno | C32: Technical Leader | E32: €/GG
A33: 23 | B33: Costo Interno | C33: Analista Programmatore | E33: €/GG
A34: 24 | B34: Costo Interno | C34: Programmatore | E34: €/GG
A35: 25 | B35: Costo Interno | C35: Architetto Applicativo (T&M) — scelta S4 | E35: €/GG
A36: 6. DRIVER OPERATIVI MAC — Da risposta RAI
A37: 26 | B37: Volumi MAC | C37: Ticket MAC totali / anno | E37: n/anno
A38: 27 | B38: Volumi MAC | C38: % ticket P1 | E38: %
A39: 28 | B39: Volumi MAC | C39: % ticket P2 | E39: %
A40: 29 | B40: Volumi MAC | C40: % ticket P3 | E40: %
A41: 30 | B41: Volumi MAC | C41: % ticket P4 | E41: %
...

Sheet A. Stima Effort
A1: Stima Effort — Servizi a Canone e T&M
A2: Effort calcolato in GG/U. Riferimenti a Sheet '0. Parametri'. Periodo base = startup 3m + operativo 36m.
A4: Servizio | B4: Capability / Profilo | C4: Driver di calcolo | D4: Formula / Volume | E4: GG/U Anno | F4: GG/U Startup (3m) | G4: GG/U Periodo Base 36m | H4: GG/U Totale 39m | I4: Metodo / Fonte
A5: A.1 SERVIZI CANONE — Effort operativo necessario (anno tipo) calcolato da driver
A6: MAC | B6: Manutenzione Correttiva (mix profili) | C6: Ticket × distribuzione × effort | D6: (N×%P1×h1+...+N×%P4×h4)/8 | E6: =('0. Parametri'!$D$37*'0. Parametri'!$D$38*'0. Parametri'!$D$42+'0. Parametri'!$D$37*'0. Parametri'!$D$39*'0. Parametri'!$D$43+'0. Parametri'!$D$37*'0. Parametri'!$D$40*'0. Parametri'!$D$44+'0. Parametri'!$D$37*'0. Parametri'!$D$41*'0. Parametri'!$D$45)/'0. Parametri'!$D$46 | F6: =0 | G6: =E6*3 | H6: =F6+G6
A7: REP | B7: Reperibilità (BE+FE) | C7: Chiamate × ore + eventi speciali | D7: (12×ch×3h+24gg×2×8h)/8 | E7: =('0. Parametri'!$D$48*12*'0. Parametri'!$D$49+'0. Parametri'!$D$50*'0. Parametri'!$D$51*'0. Parametri'!$D$52)/'0. Parametri'!$D$46 | F7: =0 | G7: =E7*3 | H7: =F7+G7
A8: GES | B8: Gestione App / DB | C8: Attività × effort | D8: 20×5 | E8: ='0. Parametri'!$D$53*'0. Parametri'!$D$54 | F8: =0 | G8: =E8*3 | H8: =F8+G8
A9: GST | B9: Gestione Standard | C9: Attività × effort | D9: 50×2 | E9: ='0. Parametri'!$D$55*'0. Parametri'!$D$56 | F9: =0 | G9: =E9*3 | H9: =F9+G9
A10: CON | B10: Conferimento (tot. 39 mesi) | C10: App × effort onboarding | D10: 5×30 = 150 GG/U TOT | E10: =('0. Parametri'!$D$57*'0. Parametri'!$D$58)/3 | F10: =0 | G10: ='0. Parametri'!$D$57*'0. Parametri'!$D$58 | H10: =F10+G10
A11: — | B11: SUBTOTALE EFFORT OPERATIVO RICHIESTO (driver-based) | C11: Somma MAC+REP+GES+GST+CON | E11: =SUM(E6:E10) | F11: =SUM(F6:F10) | G11: =SUM(G6:G10) | H11: =SUM(H6:H10)
A13: A.2 SERVIZI CANONE — Capacity team presidio fisso (Capitolato pp.13-14)
A14: Canone | B14: Service Manager / PM | C14: Capacity team presidio | D14: 1 risorsa × 220 GG/anno | E14: ='0. Parametri'!$D$24*'0. Parametri'!$D$60 | F14: =('0. Parametri'!$D$24*'0. Parametri'!$D$60)*'0. Parametri'!$D$64*('0. Parametri'!$D$61/12) | G14: =('0. Parametri'!$D$24*'0. Parametri'!$D$60)*('0. Parametri'!$D$62/12) | H14: =F14+G14
A15: Canone | B15: Team Leader d'area | C15: Capacity team presidio | D15: 4 risorse × 220 GG/anno | E15: ='0. Parametri'!$D$25*'0. Parametri'!$D$60 | F15: =('0. Parametri'!$D$25*'0. Parametri'!$D$60)*'0. Parametri'!$D$64*('0. Parametri'!$D$61/12) | G15: =('0. Parametri'!$D$25*'0. Parametri'!$D$60)*('0. Parametri'!$D$62/12) | H15: =F15+G15
A16: Canone | B16: Technical Leader | C16: Capacity team presidio | D16: 11 risorse × 220 GG/anno | E16: ='0. Parametri'!$D$26*'0. Parametri'!$D$60 | F16: =('0. Parametri'!$D$26*'0. Parametri'!$D$60)*'0. Parametri'!$D$64*('0. Parametri'!$D$61/12) | G16: =('0. Parametri'!$D$26*'0. Parametri'!$D$60)*('0. Parametri'!$D$62/12) | H16: =F16+G16
A17: Canone | B17: Analista Programmatore (canone) | C17: Capacity team presidio | D17: 12 risorse × 220 GG/anno | E17: ='0. Parametri'!$D$27*'0. Parametri'!$D$60 | F17: =('0. Parametri'!$D$27*'0. Parametri'!$D$60)*'0. Parametri'!$D$64*('0. Parametri'!$D$61/12) | G17: =('0. Parametri'!$D$27*'0. Parametri'!$D$60)*('0. Parametri'!$D$62/12) | H17: =F17+G17
A18: Canone | B18: Programmatore (canone) | C18: Capacity team presidio | D18: 14 risorse × 220 GG/anno | E18: ='0. Parametri'!$D$28*'0. Parametri'!$D$60 | F18: =('0. Parametri'!$D$28*'0. Parametri'!$D$60)*'0. Parametri'!$D$64*('0. Parametri'!$D$61/12) | G18: =('0. Parametri'!$D$28*'0. Parametri'!$D$60)*('0. Parametri'!$D$62/12) | H18: =F18+G18
A19: — | B19: TOTALE CAPACITY PRESIDIO (42 risorse) | C19: Somma profili canone | E19: =SUM(E14:E18) | F19: =SUM(F14:F18) | G19: =SUM(G14:G18) | H19: =SUM(H14:H18)
A20: NOTA: capacity presidio (=19-questa) DEVE coprire l'effort operativo richiesto (=11). Il delta rappresenta capacità libera per: gestione picchi, on-call backup, turn over, training, audit, attività non quantificate. Il canone PAGA il presidio (FTE), non l'effort puntuale. Il margine è guidato dal costo del team minimo, non dal volume MAC/REP.
A22: A.3 SERVIZI T&M — Volumi Capitolato p.36 (scelta S1) — BLOCCANTE: incoerenza Disciplinare
A23: T&M | B23: Architetto Applicativo (T&M) | C23: Volumi indicativi Capitolato | D23: 20 GG/U/anno × 3 anni | E23: ='0. Parametri'!$D$19 | F23: 0 | G23: ='0. Parametri'!$D$19*'0. Parametri'!$D$62/12 | H23: =F23+G23
A24: T&M | B24: TL/Analista funzionale (T&M) — scelta S2 | C24: Volumi indicativi Capitolato | D24: 200 GG/U/anno × 3 | E24: ='0. Parametri'!$D$20 | F24: 0 | G24: ='0. Parametri'!$D$20*'0. Parametri'!$D$62/12 | H24: =F24+G24
A25: T&M | B25: Analista Programmatore (T&M) | C25: Volumi indicativi Capitolato | D25: 500 GG/U/anno × 3 | E25: ='0. Parametri'!$D$21 | F25: 0 | G25: ='0. Parametri'!$D$21*'0. Parametri'!$D$62/12 | H25: =F25+G25
A26: T&M | B26: Programmatore (T&M) | C26: Volumi indicativi Capitolato | D26: 4.000 GG/U/anno × 3 | E26: ='0. Parametri'!$D$22 | F26: 0 | G26: ='0. Parametri'!$D$22*'0. Parametri'!$D$62/12 | H26: =F26+G26
A27: — | B27: TOTALE T&M (volumi Capitolato) | C27: Somma 4 profili T&M | E27: =SUM(E23:E26) | F27: =SUM(F23:F26) | G27: =SUM(G23:G26) | H27: =SUM(H23:H26)

Sheet B. Cost Model
A1: Cost Model — Ricavi, Costi, Margine
A2: Tutti i valori sono formule che linkano '0. Parametri' e 'A. Stima Effort'. Modifica i parametri per ricalcolare.
A4: B.1 RICAVI
A5: Voce | B5: Calcolo | C5: Lordo (pre ribasso) | D5: % Ribasso | E5: Netto (post ribasso) | F5: Riferimento | G5: Note
A6: Ricavo Startup (3 mesi) | B6: Una tantum | C6: ='0. Parametri'!$D$7 | D6: n.a. | E6: =C6
A7: Ricavo Canone Periodo Base (36m) | B7: Lordo × (1 - ribasso) | C7: ='0. Parametri'!$D$8 | D7: ='0. Parametri'!$D$66 | E7: =C7*(1-D7)
A8: Ricavo T&M Periodo Base (36m) — Capitolato | B8: Σ(volumi × tariffe) × ribasso | C8: =('0. Parametri'!$D$19*'0. Parametri'!$D$14+'0. Parametri'!$D$20*'0. Parametri'!$D$15+'0. Parametri'!$D$21*'0. Parametri'!$D$16+'0. Parametri'!$D$22*'0. Parametri'!$D$17)*('0. Parametri'!$D$62/12) | D8: ='0. Parametri'!$D$67 | E8: =C8*(1-D8)
A9: (Info) Plafond T&M residuo non utilizzato | B9: =Plafond - Ricavo T&M | C9: =MAX(0,'0. Parametri'!$D$9-C8)
A10: Oneri sicurezza | B10: Non ribassabili | C10: ='0. Parametri'!$D$12 | D10: n.a. | E10: =C10
A11: TOTALE RICAVI 39 MESI (post ribasso) | B11: Somma startup + canone + T&M + sicurezza | C11: =C6+C7+C8+C10 | E11: =E6+E7+E8+E10
A13: B.2 COSTI DIRETTI
A14: Voce | B14: Calcolo | C14: Costo Totale | D14: % | E14: Valore (€)
A15: Costo team Canone — Startup (3m, 60% capacity) | B15: Σ(N×€/GG) × 220 × (3/12) × 60% | C15: =('0. Parametri'!$D$24*'0. Parametri'!$D$30+'0. Parametri'!$D$25*'0. Parametri'!$D$31+'0. Parametri'!$D$26*'0. Parametri'!$D$32+'0. Parametri'!$D$27*'0. Parametri'!$D$33+'0. Parametri'!$D$28*'0. Parametri'!$D$34)*'0. Parametri'!$D$60*('0. Parametri'!$D$61/12)*'0. Parametri'!$D$64
A16: Costo team Canone — Periodo operativo (36m, 100%) | B16: Σ(N×€/GG) × 220 × (36/12) | C16: =('0. Parametri'!$D$24*'0. Parametri'!$D$30+'0. Parametri'!$D$25*'0. Parametri'!$D$31+'0. Parametri'!$D$26*'0. Parametri'!$D$32+'0. Parametri'!$D$27*'0. Parametri'!$D$33+'0. Parametri'!$D$28*'0. Parametri'!$D$34)*'0. Parametri'!$D$60*('0. Parametri'!$D$62/12)
A17: Costo T&M — Periodo operativo (36m) | B17: Σ(volumi × €/GG interno) × 36/12 | C17: =('0. Parametri'!$D$19*'0. Parametri'!$D$35+'0. Parametri'!$D$20*'0. Parametri'!$D$31+'0. Parametri'!$D$21*'0. Parametri'!$D$33+'0. Parametri'!$D$22*'0. Parametri'!$D$34)*('0. Parametri'!$D$62/12)
A18: TOTALE COSTI DIRETTI 39 MESI | B18: =Startup + Canone op + T&M | C18: =C15+C16+C17
A20: B.3 COSTI INDIRETTI
A21: Voce | B21: Calcolo | C21: Costo Totale | D21: % | E21: Valore (€)
A22: Overhead Project Management | B22: % × Costi Diretti | C22: =C18*'0. Parametri'!$D$70
A23: Contingency / Buffer rischio | B23: % × Costi Diretti | C23: =C18*'0. Parametri'!$D$71
A24: Effetto inflazione costo lavoro (anno 2-3) | B24: C.diretti × infl × (anni_medi) | C24: =C18*'0. Parametri'!$D$72*1.5
A25: TOTALE COSTI INDIRETTI | B25: Overhead + Contingency + Inflazione | C25: =C22+C23+C24
A27: B.4 MARGINE
A28: TOTALE COSTI 39 MESI | B28: Diretti + Indiretti | C28: =C18+C25
A29: MARGINE LORDO 39 MESI (€) | B29: Ricavi netti - Costi totali | C29: =E11-C28
A30: MARGINE LORDO 39 MESI (%) | B30: Margine / Ricavi netti | C30: =IF(E11=0,0,C29/E11)
A32: B.5 BREAKDOWN MARGINE PER COMPONENTE
A33: Componente | B33: Ricavo (€) | C33: Costo (€) | D33: Margine (€) | E33: Margine (%)
A34: Startup | B34: =E6 | C34: =C15 | D34: =B34-C34 | E34: =IF(B34=0,0,D34/B34)
A35: Canone presidio (36m) | B35: =E7 | C35: =C16 | D35: =B35-C35 | E35: =IF(B35=0,0,D35/B35)
A36: T&M (36m, vol. Capitolato) | B36: =E8 | C36: =C17 | D36: =B36-C36 | E36: =IF(B36=0,0,D36/B36)
A37: Sicurezza | B37: =E10 | C37: =0 | D37: =B37-C37 | E37: =IF(B37=0,0,D37/B37)

Sheet C. Sensitivity Pricing
A1: Sensitivity Pricing — Margine al variare di ribasso e utilizzo plafond
A2: Scenari calcolati ricostruendo la formula del margine; modifica i parametri in Sheet 0 e ricalcola.
A4: C.1 — SCENARI PREDEFINITI
A5: Scenario | B5: % Ribasso Canone | C5: % Ribasso T&M | D5: % Utilizzo Plafond T&M | E5: Volumi T&M | F5: Ricavo Canone netto | G5: Ricavo T&M netto | H5: Tot Ricavi 39m | I5: Tot Costi 39m | J5: Margine € | K5: Margine % | L5: Note
A6: Conservativo | B6: 0.05 | C6: 0.05 | D6: 0.7 | E6: Capitolato | F6: ='0. Parametri'!$D$8*(1-B6) | G6: =(('0. Parametri'!$D$19*'0. Parametri'!$D$14+'0. Parametri'!$D$20*'0. Parametri'!$D$15+'0. Parametri'!$D$21*'0. Parametri'!$D$16+'0. Parametri'!$D$22*'0. Parametri'!$D$17)*('0. Parametri'!$D$62/12))*(1-C6)*D6 | H6: ='0. Parametri'!$D$7+F6+G6+'0. Parametri'!$D$12 | I6: =((('0. Parametri'!$D$24*'0. Parametri'!$D$30+'0. Parametri'!$D$25*'0. Parametri'!$D$31+'0. Parametri'!$D$26*'0. Parametri'!$D$32+'0. Parametri'!$D$27*'0. Parametri'!$D$33+'0. Parametri'!$D$28*'0. Parametri'!$D$34)*'0. Parametri'!$D$60*('0. Parametri'!$D$62/12+'0. Parametri'!$D$61/12*'0. Parametri'!$D$64))+(('0. Parametri'!$D$19*'0. Parametri'!$D$35+'0. Parametri'!$D$20*'0. Parametri'!$D$31+'0. Parametri'!$D$21*'0. Parametri'!$D$33+'0. Parametri'!$D$22*'0. Parametri'!$D$34)*('0. Parametri'!$D$62/12))*D6)*(1+('0. Parametri'!$D$70+'0. Parametri'!$D$71+'0. Parametri'!$D$72*1.5)) | J6: =H6-I6 | K6: =IF(H6=0,0,J6/H6)
A7: Base | B7: 0.1 | C7: 0.08 | D7: 1 | E7: Capitolato | F7: ='0. Parametri'!$D$8*(1-B7) | G7: =(('0. Parametri'!$D$19*'0. Parametri'!$D$14+'0. Parametri'!$D$20*'0. Parametri'!$D$15+'0. Parametri'!$D$21*'0. Parametri'!$D$16+'0. Parametri'!$D$22*'0. Parametri'!$D$17)*('0. Parametri'!$D$62/12))*(1-C7)*D7 | H7: ='0. Parametri'!$D$7+F7+G7+'0. Parametri'!$D$12 | I7: =((('0. Parametri'!$D$24*'0. Parametri'!$D$30+'0. Parametri'!$D$25*'0. Parametri'!$D$31+'0. Parametri'!$D$26*'0. Parametri'!$D$32+'0. Parametri'!$D$27*'0. Parametri'!$D$33+'0. Parametri'!$D$28*'0. Parametri'!$D$34)*'0. Parametri'!$D$60*('0. Parametri'!$D$62/12+'0. Parametri'!$D$61/12*'0. Parametri'!$D$64))+(('0. Parametri'!$D$19*'0. Parametri'!$D$35+'0. Parametri'!$D$20*'0. Parametri'!$D$31+'0. Parametri'!$D$21*'0. Parametri'!$D$33+'0. Parametri'!$D$22*'0. Parametri'!$D$34)*('0. Parametri'!$D$62/12))*D7)*(1+('0. Parametri'!$D$70+'0. Parametri'!$D$71+'0. Parametri'!$D$72*1.5)) | J7: =H7-I7 | K7: =IF(H7=0,0,J7/H7)
A8: Aggressivo | B8: 0.15 | C8: 0.12 | D8: 1 | E8: Capitolato | F8: ='0. Parametri'!$D$8*(1-B8) | G8: =(('0. Parametri'!$D$19*'0. Parametri'!$D$14+'0. Parametri'!$D$20*'0. Parametri'!$D$15+'0. Parametri'!$D$21*'0. Parametri'!$D$16+'0. Parametri'!$D$22*'0. Parametri'!$D$17)*('0. Parametri'!$D$62/12))*(1-C8)*D8 | H8: ='0. Parametri'!$D$7+F8+G8+'0. Parametri'!$D$12 | I8: =((('0. Parametri'!$D$24*'0. Parametri'!$D$30+'0. Parametri'!$D$25*'0. Parametri'!$D$31+'0. Parametri'!$D$26*'0. Parametri'!$D$32+'0. Parametri'!$D$27*'0. Parametri'!$D$33+'0. Parametri'!$D$28*'0. Parametri'!$D$34)*'0. Parametri'!$D$60*('0. Parametri'!$D$62/12+'0. Parametri'!$D$61/12*'0. Parametri'!$D$64))+(('0. Parametri'!$D$19*'0. Parametri'!$D$35+'0. Parametri'!$D$20*'0. Parametri'!$D$31+'0. Parametri'!$D$21*'0. Parametri'!$D$33+'0. Parametri'!$D$22*'0. Parametri'!$D$34)*('0. Parametri'!$D$62/12))*D8)*(1+('0. Parametri'!$D$70+'0. Parametri'!$D$71+'0. Parametri'!$D$72*1.5)) | J8: =H8-I8 | K8: =IF(H8=0,0,J8/H8)
A9: Disciplinare-Plafond Conservativo | B9: 0.05 | C9: 0.05 | D9: 0.7 | E9: Plafond | F9: ='0. Parametri'!$D$8*(1-B9) | G9: =('0. Parametri'!$D$9)*(1-C9)*D9 | H9: ='0. Parametri'!$D$7+F9+G9+'0. Parametri'!$D$12 | I9: =((('0. Parametri'!$D$24*'0. Parametri'!$D$30+'0. Parametri'!$D$25*'0. Parametri'!$D$31+'0. Parametri'!$D$26*'0. Parametri'!$D$32+'0. Parametri'!$D$27*'0. Parametri'!$D$33+'0. Parametri'!$D$28*'0. Parametri'!$D$34)*'0. Parametri'!$D$60*('0. Parametri'!$D$62/12+'0. Parametri'!$D$61/12*'0. Parametri'!$D$64))+(('0. Parametri'!$D$19*'0. Parametri'!$D$35+'0. Parametri'!$D$20*'0. Parametri'!$D$31+'0. Parametri'!$D$21*'0. Parametri'!$D$33+'0. Parametri'!$D$22*'0. Parametri'!$D$34)*('0. Parametri'!$D$62/12))*(('0. Parametri'!$D$9*D9)/('0. Parametri'!$D$19*'0. Parametri'!$D$14+'0. Parametri'!$D$20*'0. Parametri'!$D$15+'0. Parametri'!$D$21*'0. Parametri'!$D$16+'0. Parametri'!$D$22*'0. Parametri'!$D$17)*('0. Parametri'!$D$62/12)))*(1+('0. Parametri'!$D$70+'0. Parametri'!$D$71+'0. Parametri'!$D$72*1.5)) | J9: =H9-I9 | K9: =IF(H9=0,0,J9/H9)
A10: Disciplinare-Plafond Base | B10: 0.1 | C10: 0.08 | D10: 1 | E10: Plafond | F10: ='0. Parametri'!$D$8*(1-B10) | G10: =('0. Parametri'!$D$9)*(1-C10)*D10 | H10: ='0. Parametri'!$D$7+F10+G10+'0. Parametri'!$D$12 | I10: =((('0. Parametri'!$D$24*'0. Parametri'!$D$30+'0. Parametri'!$D$25*'0. Parametri'!$D$31+'0. Parametri'!$D$26*'0. Parametri'!$D$32+'0. Parametri'!$D$27*'0. Parametri'!$D$33+'0. Parametri'!$D$28*'0. Parametri'!$D$34)*'0. Parametri'!$D$60*('0. Parametri'!$D$62/12+'0. Parametri'!$D$61/12*'0. Parametri'!$D$64))+(('0. Parametri'!$D$19*'0. Parametri'!$D$35+'0. Parametri'!$D$20*'0. Parametri'!$D$31+'0. Parametri'!$D$21*'0. Parametri'!$D$33+'0. Parametri'!$D$22*'0. Parametri'!$D$34)*('0. Parametri'!$D$62/12))*(('0. Parametri'!$D$9*D10)/('0. Parametri'!$D$19*'0. Parametri'!$D$14+'0. Parametri'!$D$20*'0. Parametri'!$D$15+'0. Parametri'!$D$21*'0. Parametri'!$D$16+'0. Parametri'!$D$22*'0. Parametri'!$D$17)*('0. Parametri'!$D$62/12)))*(1+('0. Parametri'!$D$70+'0. Parametri'!$D$71+'0. Parametri'!$D$72*1.5)) | J10: =H10-I10 | K10: =IF(H10=0,0,J10/H10)
A12: C.2 — MATRICE SENSITIVITY: Margine % per combinazioni Ribasso Canone × Ribasso T&M (volumi Capitolato, utilizzo 100%)
A13: Rib.Canone ↓ / Rib.T&M → | B13: 0 | C13: 0.05 | D13: 0.08 | E13: 0.1 | F13: 0.15
A14: 0 | B14: =(('0. Parametri'!$D$7+'0. Parametri'!$D$8*(1-0.0)+(('0. Parametri'!$D$19*'0. Parametri'!$D$14+'0. Parametri'!$D$20*'0. Parametri'!$D$15+'0. Parametri'!$D$21*'0. Parametri'!$D$16+'0. Parametri'!$D$22*'0. Parametri'!$D$17)*('0. Parametri'!$D$62/12))*(1-0.0)+'0. Parametri'!$D$12)-((('0. Parametri'!$D$24*'0. Parametri'!$D$30+'0. Parametri'!$D$25*'0. Parametri'!$D$31+'0. Parametri'!$D$26*'0. Parametri'!$D$32+'0. Parametri'!$D$27*'0. Parametri'!$D$33+'0. Parametri'!$D$28*'0. Parametri'!$D$34)*'0. Parametri'!$D$60*('0. Parametri'!$D$62/12+'0. Parametri'!$D$61/12*'0. Parametri'!$D$64))+(('0. Parametri'!$D$19*'0. Parametri'!$D$35+'0. Parametri'!$D$20*'0. Parametri'!$D$31+'0. Parametri'!$D$21*'0. Parametri'!$D$33+'0. Parametri'!$D$22*'0. Parametri'!$D$34)*('0. Parametri'!$D$62/12)))*(1+('0. Parametri'!$D$70+'0. Parametri'!$D$71+'0. Parametri'!$D$72*1.5)))/('0. Parametri'!$D$7+'0. Parametri'!$D$8*(1-0.0)+(('0. Parametri'!$D$19*'0. Parametri'!$D$14+'0. Parametri'!$D$20*'0. Parametri'!$D$15+'0. Parametri'!$D$21*'0. Parametri'!$D$16+'0. Parametri'!$D$22*'0. Parametri'!$D$17)*('0. Parametri'!$D$62/12))*(1-0.0)+'0. Parametri'!$D$12) | C14: =(('0. Parametri'!$D$7+'0. Parametri'!$D$8*(1-0.0)+(('0. Parametri'!$D$19*'0. Parametri'!$D$14+'0. Parametri'!$D$20*'0. Parametri'!$D$15+'0. Parametri'!$D$21*'0. Parametri'!$D$16+'0. Parametri'!$D$22*'0. Parametri'!$D$17)*('0. Parametri'!$D$62/12))*(1-0.05)+'0. Parametri'!$D$12)-((('0. Parametri'!$D$24*'0. Parametri'!$D$30+'0. Parametri'!$D$25*'0. Parametri'!$D$31+'0. Parametri'!$D$26*'0. Parametri'!$D$32+'0. Parametri'!$D$27*'0. Parametri'!$D$33+'0. Parametri'!$D$28*'0. Parametri'!$D$34)*'0. Parametri'!$D$60*('0. Parametri'!$D$62/12+'0. Parametri'!$D$61/12*'0. Parametri'!$D$64))+(('0. Parametri'!$D$19*'0. Parametri'!$D$35+'0. Parametri'!$D$20*'0. Parametri'!$D$31+'0. Parametri'!$D$21*'0. Parametri'!$D$33+'0. Parametri'!$D$22*'0. Parametri'!$D$34)*('0. Parametri'!$D$62/12)))*(1+('0. Parametri'!$D$70+'0. Parametri'!$D$71+'0. Parametri'!$D$72*1.5)))/('0. Parametri'!$D$7+'0. Parametri'!$D$8*(1-0.0)+(('0. Parametri'!$D$19*'0. Parametri'!$D$14+'0. Parametri'!$D$20*'0. Parametri'!$D$15+'0. Parametri'!$D$21*'0. Parametri'!$D$16+'0. Parametri'!$D$22*'0. Parametri'!$D$17)*('0. Parametri'!$D$62/12))*(1-0.05)+'0. Parametri'!$D$12) | D14: =(('0. Parametri'!$D$7+'0. Parametri'!$D$8*(1-0.0)+(('0. Parametri'!$D$19*'0. Parametri'!$D$14+'0. Parametri'!$D$20*'0. Parametri'!$D$15+'0. Parametri'!$D$21*'0. Parametri'!$D$16+'0. Parametri'!$D$22*'0. Parametri'!$D$17)*('0. Parametri'!$D$62/12))*(1-0.08)+'0. Parametri'!$D$12)-((('0. Parametri'!$D$24*'0. Parametri'!$D$30+'0. Parametri'!$D$25*'0. Parametri'!$D$31+'0. Parametri'!$D$26*'0. Parametri'!$D$32+'0. Parametri'!$D$27*'0. Parametri'!$D$33+'0. Parametri'!$D$28*'0. Parametri'!$D$34)*'0. Parametri'!$D$60*('0. Parametri'!$D$62/12+'0. Parametri'!$D$61/12*'0. Parametri'!$D$64))+(('0. Parametri'!$D$19*'0. Parametri'!$D$35+'0. Parametri'!$D$20*'0. Parametri'!$D$31+'0. Parametri'!$D$21*'0. Parametri'!$D$33+'0. Parametri'!$D$22*'0. Parametri'!$D$34)*('0. Parametri'!$D$62/12)))*(1+('0. Parametri'!$D$70+'0. Parametri'!$D$71+'0. Parametri'!$D$72*1.5)))/('0. Parametri'!$D$7+'0. Parametri'!$D$8*(1-0.0)+(('0. Parametri'!$D$19*'0. Parametri'!$D$14+'0. Parametri'!$D$20*'0. Parametri'!$D$15+'0. Parametri'!$D$21*'0. Parametri'!$D$16+'0. Parametri'!$D$22*'0. Parametri'!$D$17)*('0. Parametri'!$D$62/12))*(1-0.08)+'0. Parametri'!$D$12) | E14: =(('0. Parametri'!$D$7+'0. Parametri'!$D$8*(1-0.0)+(('0. Parametri'!$D$19*'0. Parametri'!$D$14+'0. Parametri'!$D$20*'0. Parametri'!$D$15+'0. Parametri'!$D$21*'0. Parametri'!$D$16+'0. Parametri'!$D$22*'0. Parametri'!$D$17)*('0. Parametri'!$D$62/12))*(1-0.1)+'0. Parametri'!$D$12)-((('0. Parametri'!$D$24*'0. Parametri'!$D$30+'0. Parametri'!$D$25*'0. Parametri'!$D$31+'0. Parametri'!$D$26*'0. Parametri'!$D$32+'0. Parametri'!$D$27*'0. Parametri'!$D$33+'0. Parametri'!$D$28*'0. Parametri'!$D$34)*'0. Parametri'!$D$60*('0. Parametri'!$D$62/12+'0. Parametri'!$D$61/12*'0. Parametri'!$D$64))+(('0. Parametri'!$D$19*'0. Parametri'!$D$35+'0. Parametri'!$D$20*'0. Parametri'!$D$31+'0. Parametri'!$D$21*'0. Parametri'!$D$33+'0. Parametri'!$D$22*'0. Parametri'!$D$34)*('0. Parametri'!$D$62/12)))*(1+('0. Parametri'!$D$70+'0. Parametri'!$D$71+'0. Parametri'!$D$72*1.5)))/('0. Parametri'!$D$7+'0. Parametri'!$D$8*(1-0.0)+(('0. Parametri'!$D$19*'0. Parametri'!$D$14+'0. Parametri'!$D$20*'0. Parametri'!$D$15+'0. Parametri'!$D$21*'0. Parametri'!$D$16+'0. Parametri'!$D$22*'0. Parametri'!$D$17)*('0. Parametri'!$D$62/12))*(1-0.1)+'0. Parametri'!$D$12) | F14: =(('0. Parametri'!$D$7+'0. Parametri'!$D$8*(1-0.0)+(('0. Parametri'!$D$19*'0. Parametri'!$D$14+'0. Parametri'!$D$20*'0. Parametri'!$D$15+'0. Parametri'!$D$21*'0. Parametri'!$D$16+'0. Parametri'!$D$22*'0. Parametri'!$D$17)*('0. Parametri'!$D$62/12))*(1-0.15)+'0. Parametri'!$D$12)-((('0. Parametri'!$D$24*'0. Parametri'!$D$30+'0. Parametri'!$D$25*'0. Parametri'!$D$31+'0. Parametri'!$D$26*'0. Parametri'!$D$32+'0. Parametri'!$D$27*'0. Parametri'!$D$33+'0. Parametri'!$D$28*'0. Parametri'!$D$34)*'0. Parametri'!$D$60*('0. Parametri'!$D$62/12+'0. Parametri'!$D$61/12*'0. Parametri'!$D$64))+(('0. Parametri'!$D$19*'0. Parametri'!$D$35+'0. Parametri'!$D$20*'0. Parametri'!$D$31+'0. Parametri'!$D$21*'0. Parametri'!$D$33+'0. Parametri'!$D$22*'0. Parametri'!$D$34)*('0. Parametri'!$D$62/12)))*(1+('0. Parametri'!$D$70+'0. Parametri'!$D$71+'0. Parametri'!$D$72*1.5)))/('0. Parametri'!$D$7+'0. Parametri'!$D$8*(1-0.0)+(('0. Parametri'!$D$19*'0. Parametri'!$D$14+'0. Parametri'!$D$20*'0. Parametri'!$D$15+'0. Parametri'!$D$21*'0. Parametri'!$D$16+'0. Parametri'!$D$22*'0. Parametri'!$D$17)*('0. Parametri'!$D$62/12))*(1-0.15)+'0. Parametri'!$D$12)
A15: 0.05 | B15: =(('0. Parametri'!$D$7+'0. Parametri'!$D$8*(1-0.05)+(('0. Parametri'!$D$19*'0. Parametri'!$D$14+'0. Parametri'!$D$20*'0. Parametri'!$D$15+'0. Parametri'!$D$21*'0. Parametri'!$D$16+'0. Parametri'!$D$22*'0. Parametri'!$D$17)*('0. Parametri'!$D$62/12))*(1-0.0)+'0. Parametri'!$D$12)-((('0. Parametri'!$D$24*'0. Parametri'!$D$30+'0. Parametri'!$D$25*'0. Parametri'!$D$31+'0. Parametri'!$D$26*'0. Parametri'!$D$32+'0. Parametri'!$D$27*'0. Parametri'!$D$33+'0. Parametri'!$D$28*'0. Parametri'!$D$34)*'0. Parametri'!$D$60*('0. Parametri'!$D$62/12+'0. Parametri'!$D$61/12*'0. Parametri'!$D$64))+(('0. Parametri'!$D$19*'0. Parametri'!$D$35+'0. Parametri'!$D$20*'0. Parametri'!$D$31+'0. Parametri'!$D$21*'0. Parametri'!$D$33+'0. Parametri'!$D$22*'0. Parametri'!$D$34)*('0. Parametri'!$D$62/12)))*(1+('0. Parametri'!$D$70+'0. Parametri'!$D$71+'0. Parametri'!$D$72*1.5)))/('0. Parametri'!$D$7+'0. Parametri'!$D$8*(1-0.05)+(('0. Parametri'!$D$19*'0. Parametri'!$D$14+'0. Parametri'!$D$20*'0. Parametri'!$D$15+'0. Parametri'!$D$21*'0. Parametri'!$D$16+'0. Parametri'!$D$22*'0. Parametri'!$D$17)*('0. Parametri'!$D$62/12))*(1-0.0)+'0. Parametri'!$D$12) | C15: =(('0. Parametri'!$D$7+'0. Parametri'!$D$8*(1-0.05)+(('0. Parametri'!$D$19*'0. Parametri'!$D$14+'0. Parametri'!$D$20*'0. Parametri'!$D$15+'0. Parametri'!$D$21*'0. Parametri'!$D$16+'0. Parametri'!$D$22*'0. Parametri'!$D$17)*('0. Parametri'!$D$62/12))*(1-0.05)+'0. Parametri'!$D$12)-((('0. Parametri'!$D$24*'0. Parametri'!$D$30+'0. Parametri'!$D$25*'0. Parametri'!$D$31+'0. Parametri'!$D$26*'0. Parametri'!$D$32+'0. Parametri'!$D$27*'0. Parametri'!$D$33+'0. Parametri'!$D$28*'0. Parametri'!$D$34)*'0. Parametri'!$D$60*('0. Parametri'!$D$62/12+'0. Parametri'!$D$61/12*'0. Parametri'!$D$64))+(('0. Parametri'!$D$19*'0. Parametri'!$D$35+'0. Parametri'!$D$20*'0. Parametri'!$D$31+'0. Parametri'!$D$21*'0. Parametri'!$D$33+'0. Parametri'!$D$22*'0. Parametri'!$D$34)*('0. Parametri'!$D$62/12)))*(1+('0. Parametri'!$D$70+'0. Parametri'!$D$71+'0. Parametri'!$D$72*1.5)))/('0. Parametri'!$D$7+'0. Parametri'!$D$8*(1-0.05)+(('0. Parametri'!$D$19*'0. Parametri'!$D$14+'0. Parametri'!$D$20*'0. Parametri'!$D$15+'0. Parametri'!$D$21*'0. Parametri'!$D$16+'0. Parametri'!$D$22*'0. Parametri'!$D$17)*('0. Parametri'!$D$62/12))*(1-0.05)+'0. Parametri'!$D$12) | D15: =(('0. Parametri'!$D$7+'0. Parametri'!$D$8*(1-0.05)+(('0. Parametri'!$D$19*'0. Parametri'!$D$14+'0. Parametri'!$D$20*'0. Parametri'!$D$15+'0. Parametri'!$D$21*'0. Parametri'!$D$16+'0. Parametri'!$D$22*'0. Parametri'!$D$17)*('0. Parametri'!$D$62/12))*(1-0.08)+'0. Parametri'!$D$12)-((('0. Parametri'!$D$24*'0. Parametri'!$D$30+'0. Parametri'!$D$25*'0. Parametri'!$D$31+'0. Parametri'!$D$26*'0. Parametri'!$D$32+'0. Parametri'!$D$27*'0. Parametri'!$D$33+'0. Parametri'!$D$28*'0. Parametri'!$D$34)*'0. Parametri'!$D$60*('0. Parametri'!$D$62/12+'0. Parametri'!$D$61/12*'0. Parametri'!$D$64))+(('0. Parametri'!$D$19*'0. Parametri'!$D$35+'0. Parametri'!$D$20*'0. Parametri'!$D$31+'0. Parametri'!$D$21*'0. Parametri'!$D$33+'0. Parametri'!$D$22*'0. Parametri'!$D$34)*('0. Parametri'!$D$62/12)))*(1+('0. Parametri'!$D$70+'0. Parametri'!$D$71+'0. Parametri'!$D$72*1.5)))/('0. Parametri'!$D$7+'0. Parametri'!$D$8*(1-0.05)+(('0. Parametri'!$D$19*'0. Parametri'!$D$14+'0. Parametri'!$D$20*'0. Parametri'!$D$15+'0. Parametri'!$D$21*'0. Parametri'!$D$16+'0. Parametri'!$D$22*'0. Parametri'!$D$17)*('0. Parametri'!$D$62/12))*(1-0.08)+'0. Parametri'!$D$12) | E15: =(('0. Parametri'!$D$7+'0. Parametri'!$D$8*(1-0.05)+(('0. Parametri'!$D$19*'0. Parametri'!$D$14+'0. Parametri'!$D$20*'0. Parametri'!$D$15+'0. Parametri'!$D$21*'0. Parametri'!$D$16+'0. Parametri'!$D$22*'0. Parametri'!$D$17)*('0. Parametri'!$D$62/12))*(1-0.1)+'0. Parametri'!$D$12)-((('0. Parametri'!$D$24*'0. Parametri'!$D$30+'0. Parametri'!$D$25*'0. Parametri'!$D$31+'0. Parametri'!$D$26*'0. Parametri'!$D$32+'0. Parametri'!$D$27*'0. Parametri'!$D$33+'0. Parametri'!$D$28*'0. Parametri'!$D$34)*'0. Parametri'!$D$60*('0. Parametri'!$D$62/12+'0. Parametri'!$D$61/12*'0. Parametri'!$D$64))+(('0. Parametri'!$D$19*'0. Parametri'!$D$35+'0. Parametri'!$D$20*'0. Parametri'!$D$31+'0. Parametri'!$D$21*'0. Parametri'!$D$33+'0. Parametri'!$D$22*'0. Parametri'!$D$34)*('0. Parametri'!$D$62/12)))*(1+('0. Parametri'!$D$70+'0. Parametri'!$D$71+'0. Parametri'!$D$72*1.5)))/('0. Parametri'!$D$7+'0. Parametri'!$D$8*(1-0.05)+(('0. Parametri'!$D$19*'0. Parametri'!$D$14+'0. Parametri'!$D$20*'0. Parametri'!$D$15+'0. Parametri'!$D$21*'0. Parametri'!$D$16+'0. Parametri'!$D$22*'0. Parametri'!$D$17)*('0. Parametri'!$D$62/12))*(1-0.1)+'0. Parametri'!$D$12) | F15: =(('0. Parametri'!$D$7+'0. Parametri'!$D$8*(1-0.05)+(('0. Parametri'!$D$19*'0. Parametri'!$D$14+'0. Parametri'!$D$20*'0. Parametri'!$D$15+'0. Parametri'!$D$21*'0. Parametri'!$D$16+'0. Parametri'!$D$22*'0. Parametri'!$D$17)*('0. Parametri'!$D$62/12))*(1-0.15)+'0. Parametri'!$D$12)-((('0. Parametri'!$D$24*'0. Parametri'!$D$30+'0. Parametri'!$D$25*'0. Parametri'!$D$31+'0. Parametri'!$D$26*'0. Parametri'!$D$32+'0. Parametri'!$D$27*'0. Parametri'!$D$33+'0. Parametri'!$D$28*'0. Parametri'!$D$34)*'0. Parametri'!$D$60*('0. Parametri'!$D$62/12+'0. Parametri'!$D$61/12*'0. Parametri'!$D$64))+(('0. Parametri'!$D$19*'0. Parametri'!$D$35+'0. Parametri'!$D$20*'0. Parametri'!$D$31+'0. Parametri'!$D$21*'0. Parametri'!$D$33+'0. Parametri'!$D$22*'0. Parametri'!$D$34)*('0. Parametri'!$D$62/12)))*(1+('0. Parametri'!$D$70+'0. Parametri'!$D$71+'0. Parametri'!$D$72*1.5)))/('0. Parametri'!$D$7+'0. Parametri'!$D$8*(1-0.05)+(('0. Parametri'!$D$19*'0. Parametri'!$D$14+'0. Parametri'!$D$20*'0. Parametri'!$D$15+'0. Parametri'!$D$21*'0. Parametri'!$D$16+'0. Parametri'!$D$22*'0. Parametri'!$D$17)*('0. Parametri'!$D$62/12))*(1-0.15)+'0. Parametri'!$D$12)
A16: 0.1 | B16: =(('0. Parametri'!$D$7+'0. Parametri'!$D$8*(1-0.1)+(('0. Parametri'!$D$19*'0. Parametri'!$D$14+'0. Parametri'!$D$20*'0. Parametri'!$D$15+'0. Parametri'!$D$21*'0. Parametri'!$D$16+'0. Parametri'!$D$22*'0. Parametri'!$D$17)*('0. Parametri'!$D$62/12))*(1-0.0)+'0. Parametri'!$D$12)-((('0. Parametri'!$D$24*'0. Parametri'!$D$30+'0. Parametri'!$D$25*'0. Parametri'!$D$31+'0. Parametri'!$D$26*'0. Parametri'!$D$32+'0. Parametri'!$D$27*'0. Parametri'!$D$33+'0. Parametri'!$D$28*'0. Parametri'!$D$34)*'0. Parametri'!$D$60*('0. Parametri'!$D$62/12+'0. Parametri'!$D$61/12*'0. Parametri'!$D$64))+(('0. Parametri'!$D$19*'0. Parametri'!$D$35+'0. Parametri'!$D$20*'0. Parametri'!$D$31+'0. Parametri'!$D$21*'0. Parametri'!$D$33+'0. Parametri'!$D$22*'0. Parametri'!$D$34)*('0. Parametri'!$D$62/12)))*(1+('0. Parametri'!$D$70+'0. Parametri'!$D$71+'0. Parametri'!$D$72*1.5)))/('0. Parametri'!$D$7+'0. Parametri'!$D$8*(1-0.1)+(('0. Parametri'!$D$19*'0. Parametri'!$D$14+'0. Parametri'!$D$20*'0. Parametri'!$D$15+'0. Parametri'!$D$21*'0. Parametri'!$D$16+'0. Parametri'!$D$22*'0. Parametri'!$D$17)*('0. Parametri'!$D$62/12))*(1-0.0)+'0. Parametri'!$D$12) | C16: =(('0. Parametri'!$D$7+'0. Parametri'!$D$8*(1-0.1)+(('0. Parametri'!$D$19*'0. Parametri'!$D$14+'0. Parametri'!$D$20*'0. Parametri'!$D$15+'0. Parametri'!$D$21*'0. Parametri'!$D$16+'0. Parametri'!$D$22*'0. Parametri'!$D$17)*('0. Parametri'!$D$62/12))*(1-0.05)+'0. Parametri'!$D$12)-((('0. Parametri'!$D$24*'0. Parametri'!$D$30+'0. Parametri'!$D$25*'0. Parametri'!$D$31+'0. Parametri'!$D$26*'0. Parametri'!$D$32+'0. Parametri'!$D$27*'0. Parametri'!$D$33+'0. Parametri'!$D$28*'0. Parametri'!$D$34)*'0. Parametri'!$D$60*('0. Parametri'!$D$62/12+'0. Parametri'!$D$61/12*'0. Parametri'!$D$64))+(('0. Parametri'!$D$19*'0. Parametri'!$D$35+'0. Parametri'!$D$20*'0. Parametri'!$D$31+'0. Parametri'!$D$21*'0. Parametri'!$D$33+'0. Parametri'!$D$22*'0. Parametri'!$D$34)*('0. Parametri'!$D$62/12)))*(1+('0. Parametri'!$D$70+'0. Parametri'!$D$71+'0. Parametri'!$D$72*1.5)))/('0. Parametri'!$D$7+'0. Parametri'!$D$8*(1-0.1)+(('0. Parametri'!$D$19*'0. Parametri'!$D$14+'0. Parametri'!$D$20*'0. Parametri'!$D$15+'0. Parametri'!$D$21*'0. Parametri'!$D$16+'0. Parametri'!$D$22*'0. Parametri'!$D$17)*('0. Parametri'!$D$62/12))*(1-0.05)+'0. Parametri'!$D$12) | D16: =(('0. Parametri'!$D$7+'0. Parametri'!$D$8*(1-0.1)+(('0. Parametri'!$D$19*'0. Parametri'!$D$14+'0. Parametri'!$D$20*'0. Parametri'!$D$15+'0. Parametri'!$D$21*'0. Parametri'!$D$16+'0. Parametri'!$D$22*'0. Parametri'!$D$17)*('0. Parametri'!$D$62/12))*(1-0.08)+'0. Parametri'!$D$12)-((('0. Parametri'!$D$24*'0. Parametri'!$D$30+'0. Parametri'!$D$25*'0. Parametri'!$D$31+'0. Parametri'!$D$26*'0. Parametri'!$D$32+'0. Parametri'!$D$27*'0. Parametri'!$D$33+'0. Parametri'!$D$28*'0. Parametri'!$D$34)*'0. Parametri'!$D$60*('0. Parametri'!$D$62/12+'0. Parametri'!$D$61/12*'0. Parametri'!$D$64))+(('0. Parametri'!$D$19*'0. Parametri'!$D$35+'0. Parametri'!$D$20*'0. Parametri'!$D$31+'0. Parametri'!$D$21*'0. Parametri'!$D$33+'0. Parametri'!$D$22*'0. Parametri'!$D$34)*('0. Parametri'!$D$62/12)))*(1+('0. Parametri'!$D$70+'0. Parametri'!$D$71+'0. Parametri'!$D$72*1.5)))/('0. Parametri'!$D$7+'0. Parametri'!$D$8*(1-0.1)+(('0. Parametri'!$D$19*'0. Parametri'!$D$14+'0. Parametri'!$D$20*'0. Parametri'!$D$15+'0. Parametri'!$D$21*'0. Parametri'!$D$16+'0. Parametri'!$D$22*'0. Parametri'!$D$17)*('0. Parametri'!$D$62/12))*(1-0.08)+'0. Parametri'!$D$12) | E16: =(('0. Parametri'!$D$7+'0. Parametri'!$D$8*(1-0.1)+(('0. Parametri'!$D$19*'0. Parametri'!$D$14+'0. Parametri'!$D$20*'0. Parametri'!$D$15+'0. Parametri'!$D$21*'0. Parametri'!$D$16+'0. Parametri'!$D$22*'0. Parametri'!$D$17)*('0. Parametri'!$D$62/12))*(1-0.1)+'0. Parametri'!$D$12)-((('0. Parametri'!$D$24*'0. Parametri'!$D$30+'0. Parametri'!$D$25*'0. Parametri'!$D$31+'0. Parametri'!$D$26*'0. Parametri'!$D$32+'0. Parametri'!$D$27*'0. Parametri'!$D$33+'0. Parametri'!$D$28*'0. Parametri'!$D$34)*'0. Parametri'!$D$60*('0. Parametri'!$D$62/12+'0. Parametri'!$D$61/12*'0. Parametri'!$D$64))+(('0. Parametri'!$D$19*'0. Parametri'!$D$35+'0. Parametri'!$D$20*'0. Parametri'!$D$31+'0. Parametri'!$D$21*'0. Parametri'!$D$33+'0. Parametri'!$D$22*'0. Parametri'!$D$34)*('0. Parametri'!$D$62/12)))*(1+('0. Parametri'!$D$70+'0. Parametri'!$D$71+'0. Parametri'!$D$72*1.5)))/('0. Parametri'!$D$7+'0. Parametri'!$D$8*(1-0.1)+(('0. Parametri'!$D$19*'0. Parametri'!$D$14+'0. Parametri'!$D$20*'0. Parametri'!$D$15+'0. Parametri'!$D$21*'0. Parametri'!$D$16+'0. Parametri'!$D$22*'0. Parametri'!$D$17)*('0. Parametri'!$D$62/12))*(1-0.1)+'0. Parametri'!$D$12) | F16: =(('0. Parametri'!$D$7+'0. Parametri'!$D$8*(1-0.1)+(('0. Parametri'!$D$19*'0. Parametri'!$D$14+'0. Parametri'!$D$20*'0. Parametri'!$D$15+'0. Parametri'!$D$21*'0. Parametri'!$D$16+'0. Parametri'!$D$22*'0. Parametri'!$D$17)*('0. Parametri'!$D$62/12))*(1-0.15)+'0. Parametri'!$D$12)-((('0. Parametri'!$D$24*'0. Parametri'!$D$30+'0. Parametri'!$D$25*'0. Parametri'!$D$31+'0. Parametri'!$D$26*'0. Parametri'!$D$32+'0. Parametri'!$D$27*'0. Parametri'!$D$33+'0. Parametri'!$D$28*'0. Parametri'!$D$34)*'0. Parametri'!$D$60*('0. Parametri'!$D$62/12+'0. Parametri'!$D$61/12*'0. Parametri'!$D$64))+(('0. Parametri'!$D$19*'0. Parametri'!$D$35+'0. Parametri'!$D$20*'0. Parametri'!$D$31+'0. Parametri'!$D$21*'0. Parametri'!$D$33+'0. Parametri'!$D$22*'0. Parametri'!$D$34)*('0. Parametri'!$D$62/12)))*(1+('0. Parametri'!$D$70+'0. Parametri'!$D$71+'0. Parametri'!$D$72*1.5)))/('0. Parametri'!$D$7+'0. Parametri'!$D$8*(1-0.1)+(('0. Parametri'!$D$19*'0. Parametri'!$D$14+'0. Parametri'!$D$20*'0. Parametri'!$D$15+'0. Parametri'!$D$21*'0. Parametri'!$D$16+'0. Parametri'!$D$22*'0. Parametri'!$D$17)*('0. Parametri'!$D$62/12))*(1-0.15)+'0. Parametri'!$D$12)
A17: 0.15 | B17: =(('0. Parametri'!$D$7+'0. Parametri'!$D$8*(1-0.15)+(('0. Parametri'!$D$19*'0. Parametri'!$D$14+'0. Parametri'!$D$20*'0. Parametri'!$D$15+'0. Parametri'!$D$21*'0. Parametri'!$D$16+'0. Parametri'!$D$22*'0. Parametri'!$D$17)*('0. Parametri'!$D$62/12))*(1-0.0)+'0. Parametri'!$D$12)-((('0. Parametri'!$D$24*'0. Parametri'!$D$30+'0. Parametri'!$D$25*'0. Parametri'!$D$31+'0. Parametri'!$D$26*'0. Parametri'!$D$32+'0. Parametri'!$D$27*'0. Parametri'!$D$33+'0. Parametri'!$D$28*'0. Parametri'!$D$34)*'0. Parametri'!$D$60*('0. Parametri'!$D$62/12+'0. Parametri'!$D$61/12*'0. Parametri'!$D$64))+(('0. Parametri'!$D$19*'0. Parametri'!$D$35+'0. Parametri'!$D$20*'0. Parametri'!$D$31+'0. Parametri'!$D$21*'0. Parametri'!$D$33+'0. Parametri'!$D$22*'0. Parametri'!$D$34)*('0. Parametri'!$D$62/12)))*(1+('0. Parametri'!$D$70+'0. Parametri'!$D$71+'0. Parametri'!$D$72*1.5)))/('0. Parametri'!$D$7+'0. Parametri'!$D$8*(1-0.15)+(('0. Parametri'!$D$19*'0. Parametri'!$D$14+'0. Parametri'!$D$20*'0. Parametri'!$D$15+'0. Parametri'!$D$21*'0. Parametri'!$D$16+'0. Parametri'!$D$22*'0. Parametri'!$D$17)*('0. Parametri'!$D$62/12))*(1-0.0)+'0. Parametri'!$D$12) | C17: =(('0. Parametri'!$D$7+'0. Parametri'!$D$8*(1-0.15)+(('0. Parametri'!$D$19*'0. Parametri'!$D$14+'0. Parametri'!$D$20*'0. Parametri'!$D$15+'0. Parametri'!$D$21*'0. Parametri'!$D$16+'0. Parametri'!$D$22*'0. Parametri'!$D$17)*('0. Parametri'!$D$62/12))*(1-0.05)+'0. Parametri'!$D$12)-((('0. Parametri'!$D$24*'0. Parametri'!$D$30+'0. Parametri'!$D$25*'0. Parametri'!$D$31+'0. Parametri'!$D$26*'0. Parametri'!$D$32+'0. Parametri'!$D$27*'0. Parametri'!$D$33+'0. Parametri'!$D$28*'0. Parametri'!$D$34)*'0. Parametri'!$D$60*('0. Parametri'!$D$62/12+'0. Parametri'!$D$61/12*'0. Parametri'!$D$64))+(('0. Parametri'!$D$19*'0. Parametri'!$D$35+'0. Parametri'!$D$20*'0. Parametri'!$D$31+'0. Parametri'!$D$21*'0. Parametri'!$D$33+'0. Parametri'!$D$22*'0. Parametri'!$D$34)*('0. Parametri'!$D$62/12)))*(1+('0. Parametri'!$D$70+'0. Parametri'!$D$71+'0. Parametri'!$D$72*1.5)))/('0. Parametri'!$D$7+'0. Parametri'!$D$8*(1-0.15)+(('0. Parametri'!$D$19*'0. Parametri'!$D$14+'0. Parametri'!$D$20*'0. Parametri'!$D$15+'0. Parametri'!$D$21*'0. Parametri'!$D$16+'0. Parametri'!$D$22*'0. Parametri'!$D$17)*('0. Parametri'!$D$62/12))*(1-0.05)+'0. Parametri'!$D$12) | D17: =(('0. Parametri'!$D$7+'0. Parametri'!$D$8*(1-0.15)+(('0. Parametri'!$D$19*'0. Parametri'!$D$14+'0. Parametri'!$D$20*'0. Parametri'!$D$15+'0. Parametri'!$D$21*'0. Parametri'!$D$16+'0. Parametri'!$D$22*'0. Parametri'!$D$17)*('0. Parametri'!$D$62/12))*(1-0.08)+'0. Parametri'!$D$12)-((('0. Parametri'!$D$24*'0. Parametri'!$D$30+'0. Parametri'!$D$25*'0. Parametri'!$D$31+'0. Parametri'!$D$26*'0. Parametri'!$D$32+'0. Parametri'!$D$27*'0. Parametri'!$D$33+'0. Parametri'!$D$28*'0. Parametri'!$D$34)*'0. Parametri'!$D$60*('0. Parametri'!$D$62/12+'0. Parametri'!$D$61/12*'0. Parametri'!$D$64))+(('0. Parametri'!$D$19*'0. Parametri'!$D$35+'0. Parametri'!$D$20*'0. Parametri'!$D$31+'0. Parametri'!$D$21*'0. Parametri'!$D$33+'0. Parametri'!$D$22*'0. Parametri'!$D$34)*('0. Parametri'!$D$62/12)))*(1+('0. Parametri'!$D$70+'0. Parametri'!$D$71+'0. Parametri'!$D$72*1.5)))/('0. Parametri'!$D$7+'0. Parametri'!$D$8*(1-0.15)+(('0. Parametri'!$D$19*'0. Parametri'!$D$14+'0. Parametri'!$D$20*'0. Parametri'!$D$15+'0. Parametri'!$D$21*'0. Parametri'!$D$16+'0. Parametri'!$D$22*'0. Parametri'!$D$17)*('0. Parametri'!$D$62/12))*(1-0.08)+'0. Parametri'!$D$12) | E17: =(('0. Parametri'!$D$7+'0. Parametri'!$D$8*(1-0.15)+(('0. Parametri'!$D$19*'0. Parametri'!$D$14+'0. Parametri'!$D$20*'0. Parametri'!$D$15+'0. Parametri'!$D$21*'0. Parametri'!$D$16+'0. Parametri'!$D$22*'0. Parametri'!$D$17)*('0. Parametri'!$D$62/12))*(1-0.1)+'0. Parametri'!$D$12)-((('0. Parametri'!$D$24*'0. Parametri'!$D$30+'0. Parametri'!$D$25*'0. Parametri'!$D$31+'0. Parametri'!$D$26*'0. Parametri'!$D$32+'0. Parametri'!$D$27*'0. Parametri'!$D$33+'0. Parametri'!$D$28*'0. Parametri'!$D$34)*'0. Parametri'!$D$60*('0. Parametri'!$D$62/12+'0. Parametri'!$D$61/12*'0. Parametri'!$D$64))+(('0. Parametri'!$D$19*'0. Parametri'!$D$35+'0. Parametri'!$D$20*'0. Parametri'!$D$31+'0. Parametri'!$D$21*'0. Parametri'!$D$33+'0. Parametri'!$D$22*'0. Parametri'!$D$34)*('0. Parametri'!$D$62/12)))*(1+('0. Parametri'!$D$70+'0. Parametri'!$D$71+'0. Parametri'!$D$72*1.5)))/('0. Parametri'!$D$7+'0. Parametri'!$D$8*(1-0.15)+(('0. Parametri'!$D$19*'0. Parametri'!$D$14+'0. Parametri'!$D$20*'0. Parametri'!$D$15+'0. Parametri'!$D$21*'0. Parametri'!$D$16+'0. Parametri'!$D$22*'0. Parametri'!$D$17)*('0. Parametri'!$D$62/12))*(1-0.1)+'0. Parametri'!$D$12) | F17: =(('0. Parametri'!$D$7+'0. Parametri'!$D$8*(1-0.15)+(('0. Parametri'!$D$19*'0. Parametri'!$D$14+'0. Parametri'!$D$20*'0. Parametri'!$D$15+'0. Parametri'!$D$21*'0. Parametri'!$D$16+'0. Parametri'!$D$22*'0. Parametri'!$D$17)*('0. Parametri'!$D$62/12))*(1-0.15)+'0. Parametri'!$D$12)-((('0. Parametri'!$D$24*'0. Parametri'!$D$30+'0. Parametri'!$D$25*'0. Parametri'!$D$31+'0. Parametri'!$D$26*'0. Parametri'!$D$32+'0. Parametri'!$D$27*'0. Parametri'!$D$33+'0. Parametri'!$D$28*'0. Parametri'!$D$34)*'0. Parametri'!$D$60*('0. Parametri'!$D$62/12+'0. Parametri'!$D$61/12*'0. Parametri'!$D$64))+(('0. Parametri'!$D$19*'0. Parametri'!$D$35+'0. Parametri'!$D$20*'0. Parametri'!$D$31+'0. Parametri'!$D$21*'0. Parametri'!$D$33+'0. Parametri'!$D$22*'0. Parametri'!$D$34)*('0. Parametri'!$D$62/12)))*(1+('0. Parametri'!$D$70+'0. Parametri'!$D$71+'0. Parametri'!$D$72*1.5)))/('0. Parametri'!$D$7+'0. Parametri'!$D$8*(1-0.15)+(('0. Parametri'!$D$19*'0. Parametri'!$D$14+'0. Parametri'!$D$20*'0. Parametri'!$D$15+'0. Parametri'!$D$21*'0. Parametri'!$D$16+'0. Parametri'!$D$22*'0. Parametri'!$D$17)*('0. Parametri'!$D$62/12))*(1-0.15)+'0. Parametri'!$D$12)
A18: 0.2 | B18: =(('0. Parametri'!$D$7+'0. Parametri'!$D$8*(1-0.2)+(('0. Parametri'!$D$19*'0. Parametri'!$D$14+'0. Parametri'!$D$20*'0. Parametri'!$D$15+'0. Parametri'!$D$21*'0. Parametri'!$D$16+'0. Parametri'!$D$22*'0. Parametri'!$D$17)*('0. Parametri'!$D$62/12))*(1-0.0)+'0. Parametri'!$D$12)-((('0. Parametri'!$D$24*'0. Parametri'!$D$30+'0. Parametri'!$D$25*'0. Parametri'!$D$31+'0. Parametri'!$D$26*'0. Parametri'!$D$32+'0. Parametri'!$D$27*'0. Parametri'!$D$33+'0. Parametri'!$D$28*'0. Parametri'!$D$34)*'0. Parametri'!$D$60*('0. Parametri'!$D$62/12+'0. Parametri'!$D$61/12*'0. Parametri'!$D$64))+(('0. Parametri'!$D$19*'0. Parametri'!$D$35+'0. Parametri'!$D$20*'0. Parametri'!$D$31+'0. Parametri'!$D$21*'0. Parametri'!$D$33+'0. Parametri'!$D$22*'0. Parametri'!$D$34)*('0. Parametri'!$D$62/12)))*(1+('0. Parametri'!$D$70+'0. Parametri'!$D$71+'0. Parametri'!$D$72*1.5)))/('0. Parametri'!$D$7+'0. Parametri'!$D$8*(1-0.2)+(('0. Parametri'!$D$19*'0. Parametri'!$D$14+'0. Parametri'!$D$20*'0. Parametri'!$D$15+'0. Parametri'!$D$21*'0. Parametri'!$D$16+'0. Parametri'!$D$22*'0. Parametri'!$D$17)*('0. Parametri'!$D$62/12))*(1-0.0)+'0. Parametri'!$D$12) | C18: =(('0. Parametri'!$D$7+'0. Parametri'!$D$8*(1-0.2)+(('0. Parametri'!$D$19*'0. Parametri'!$D$14+'0. Parametri'!$D$20*'0. Parametri'!$D$15+'0. Parametri'!$D$21*'0. Parametri'!$D$16+'0. Parametri'!$D$22*'0. Parametri'!$D$17)*('0. Parametri'!$D$62/12))*(1-0.05)+'0. Parametri'!$D$12)-((('0. Parametri'!$D$24*'0. Parametri'!$D$30+'0. Parametri'!$D$25*'0. Parametri'!$D$31+'0. Parametri'!$D$26*'0. Parametri'!$D$32+'0. Parametri'!$D$27*'0. Parametri'!$D$33+'0. Parametri'!$D$28*'0. Parametri'!$D$34)*'0. Parametri'!$D$60*('0. Parametri'!$D$62/12+'0. Parametri'!$D$61/12*'0. Parametri'!$D$64))+(('0. Parametri'!$D$19*'0. Parametri'!$D$35+'0. Parametri'!$D$20*'0. Parametri'!$D$31+'0. Parametri'!$D$21*'0. Parametri'!$D$33+'0. Parametri'!$D$22*'0. Parametri'!$D$34)*('0. Parametri'!$D$62/12)))*(1+('0. Parametri'!$D$70+'0. Parametri'!$D$71+'0. Parametri'!$D$72*1.5)))/('0. Parametri'!$D$7+'0. Parametri'!$D$8*(1-0.2)+(('0. Parametri'!$D$19*'0. Parametri'!$D$14+'0. Parametri'!$D$20*'0. Parametri'!$D$15+'0. Parametri'!$D$21*'0. Parametri'!$D$16+'0. Parametri'!$D$22*'0. Parametri'!$D$17)*('0. Parametri'!$D$62/12))*(1-0.05)+'0. Parametri'!$D$12) | D18: =(('0. Parametri'!$D$7+'0. Parametri'!$D$8*(1-0.2)+(('0. Parametri'!$D$19*'0. Parametri'!$D$14+'0. Parametri'!$D$20*'0. Parametri'!$D$15+'0. Parametri'!$D$21*'0. Parametri'!$D$16+'0. Parametri'!$D$22*'0. Parametri'!$D$17)*('0. Parametri'!$D$62/12))*(1-0.08)+'0. Parametri'!$D$12)-((('0. Parametri'!$D$24*'0. Parametri'!$D$30+'0. Parametri'!$D$25*'0. Parametri'!$D$31+'0. Parametri'!$D$26*'0. Parametri'!$D$32+'0. Parametri'!$D$27*'0. Parametri'!$D$33+'0. Parametri'!$D$28*'0. Parametri'!$D$34)*'0. Parametri'!$D$60*('0. Parametri'!$D$62/12+'0. Parametri'!$D$61/12*'0. Parametri'!$D$64))+(('0. Parametri'!$D$19*'0. Parametri'!$D$35+'0. Parametri'!$D$20*'0. Parametri'!$D$31+'0. Parametri'!$D$21*'0. Parametri'!$D$33+'0. Parametri'!$D$22*'0. Parametri'!$D$34)*('0. Parametri'!$D$62/12)))*(1+('0. Parametri'!$D$70+'0. Parametri'!$D$71+'0. Parametri'!$D$72*1.5)))/('0. Parametri'!$D$7+'0. Parametri'!$D$8*(1-0.2)+(('0. Parametri'!$D$19*'0. Parametri'!$D$14+'0. Parametri'!$D$20*'0. Parametri'!$D$15+'0. Parametri'!$D$21*'0. Parametri'!$D$16+'0. Parametri'!$D$22*'0. Parametri'!$D$17)*('0. Parametri'!$D$62/12))*(1-0.08)+'0. Parametri'!$D$12) | E18: =(('0. Parametri'!$D$7+'0. Parametri'!$D$8*(1-0.2)+(('0. Parametri'!$D$19*'0. Parametri'!$D$14+'0. Parametri'!$D$20*'0. Parametri'!$D$15+'0. Parametri'!$D$21*'0. Parametri'!$D$16+'0. Parametri'!$D$22*'0. Parametri'!$D$17)*('0. Parametri'!$D$62/12))*(1-0.1)+'0. Parametri'!$D$12)-((('0. Parametri'!$D$24*'0. Parametri'!$D$30+'0. Parametri'!$D$25*'0. Parametri'!$D$31+'0. Parametri'!$D$26*'0. Parametri'!$D$32+'0. Parametri'!$D$27*'0. Parametri'!$D$33+'0. Parametri'!$D$28*'0. Parametri'!$D$34)*'0. Parametri'!$D$60*('0. Parametri'!$D$62/12+'0. Parametri'!$D$61/12*'0. Parametri'!$D$64))+(('0. Parametri'!$D$19*'0. Parametri'!$D$35+'0. Parametri'!$D$20*'0. Parametri'!$D$31+'0. Parametri'!$D$21*'0. Parametri'!$D$33+'0. Parametri'!$D$22*'0. Parametri'!$D$34)*('0. Parametri'!$D$62/12)))*(1+('0. Parametri'!$D$70+'0. Parametri'!$D$71+'0. Parametri'!$D$72*1.5)))/('0. Parametri'!$D$7+'0. Parametri'!$D$8*(1-0.2)+(('0. Parametri'!$D$19*'0. Parametri'!$D$14+'0. Parametri'!$D$20*'0. Parametri'!$D$15+'0. Parametri'!$D$21*'0. Parametri'!$D$16+'0. Parametri'!$D$22*'0. Parametri'!$D$17)*('0. Parametri'!$D$62/12))*(1-0.1)+'0. Parametri'!$D$12) | F18: =(('0. Parametri'!$D$7+'0. Parametri'!$D$8*(1-0.2)+(('0. Parametri'!$D$19*'0. Parametri'!$D$14+'0. Parametri'!$D$20*'0. Parametri'!$D$15+'0. Parametri'!$D$21*'0. Parametri'!$D$16+'0. Parametri'!$D$22*'0. Parametri'!$D$17)*('0. Parametri'!$D$62/12))*(1-0.15)+'0. Parametri'!$D$12)-((('0. Parametri'!$D$24*'0. Parametri'!$D$30+'0. Parametri'!$D$25*'0. Parametri'!$D$31+'0. Parametri'!$D$26*'0. Parametri'!$D$32+'0. Parametri'!$D$27*'0. Parametri'!$D$33+'0. Parametri'!$D$28*'0. Parametri'!$D$34)*'0. Parametri'!$D$60*('0. Parametri'!$D$62/12+'0. Parametri'!$D$61/12*'0. Parametri'!$D$64))+(('0. Parametri'!$D$19*'0. Parametri'!$D$35+'0. Parametri'!$D$20*'0. Parametri'!$D$31+'0. Parametri'!$D$21*'0. Parametri'!$D$33+'0. Parametri'!$D$22*'0. Parametri'!$D$34)*('0. Parametri'!$D$62/12)))*(1+('0. Parametri'!$D$70+'0. Parametri'!$D$71+'0. Parametri'!$D$72*1.5)))/('0. Parametri'!$D$7+'0. Parametri'!$D$8*(1-0.2)+(('0. Parametri'!$D$19*'0. Parametri'!$D$14+'0. Parametri'!$D$20*'0. Parametri'!$D$15+'0. Parametri'!$D$21*'0. Parametri'!$D$16+'0. Parametri'!$D$22*'0. Parametri'!$D$17)*('0. Parametri'!$D$62/12))*(1-0.15)+'0. Parametri'!$D$12)
A20: Lettura matrice: ogni cella = margine % atteso 39 mesi con quella combinazione di ribasso. Verde = margine positivo; rosso = margine negativo. Identifica il 'floor' di ribasso compatibile con margine target.

Sheet D. Risk Register Stima
A1: Risk Register Stima — Rischi associati ad assunzioni e chiarimenti aperti
A2: Probabilità: A=Alta, M=Media, B=Bassa | Impatto € = stima ordine di grandezza su margine 39 mesi
A4: # | B4: Rischio | C4: Origine (Sheet 8/9) | D4: Impatto stimato € | E4: Probabilità | F4: Severity | G4: Mitigazione | H4: Owner

Sheet _Esempi
A1: _Esempi — Riferimento di compilazione (Cost Model)
A2: Esempi reali estratti dalla gara RAI – RFP Servizi a Progetto Sistemi Informativi (CIG BB2480578E). Servono per allineare formato, granularità e tono dei contenuti dei 5 sheet. NON copiare i valori — copia il PATTERN. IMPORTANTE: lo Sheet 0 è l'unico in cui si carica input; gli altri sono interamente formula-driven.
A4: 0. Parametri
A5: Esempio VERDE — Economics di gara (parametro certo da Disciplinare)
A6: col A | B6: 1
A7: col B | B7: Valore Appalto
A8: col C | B8: Startup / affiancamento (3 mesi) — non ribassabile
A9: col D | B9: 341220
A10: col E | B10: €
A11: col F | B11: Disciplinare p.11-12
A12: col G | B12: Una tantum, fisso
A15: 0. Parametri
A16: Esempio GIALLO — Assunzione operativa (% ticket P1 MAC)
A17: col A | B17: 27
A18: col B | B18: Volumi MAC
A19: col C | B19: % ticket P1
A20: col D | B20: 0.05
A21: col E | B21: %
A22: col F | B22: Assunzione operativa
A23: col G | B23: Sheet 6 #1 originale
A26: 0. Parametri
A27: Esempio ROSSO — Bloccante (Volumi T&M con incoerenza Capitolato vs Disciplinare)
A28: col A | B28: 11
A29: col B | B29: Volumi T&M
A30: col C | B30: Architetto Applicativo — GG/U/anno
A31: col D | B31: 20
A32: col E | B32: GG/U/anno
A33: col F | B33: Capitolato p.36
A34: col G | B34: Bloccante #1 non risolto: Disciplinare riporta 540 su 36m (~180/anno) ma usato 20/anno (fonte Capitolato p.36)
A37: A. Stima Effort
A38: Esempio servizio Canone con formula da driver (MAC)
A39: col A | B39: MAC
A40: col B | B40: Manutenzione Correttiva (mix profili)
A41: col C | B41: Ticket × distribuzione × effort
A42: col D | B42: (N×%P1×h1+...+N×%P4×h4)/8
A43: col E | B43: ↳ =('0. Parametri'!$D$37*'0. Parametri'!$D$38*'0. Parametri'!$D$42+'0. Parametri'!$D$37*'0. Parametri'!$D$39*'0. Parametri'!$D$43+'0. Parametri'!$D$37*'0. Parametri'!$D$40*'0. Parametri'!$D$44+'0. Parametri'!$D$37*'0. Parametri'!$D$41*'0. Parametri'!$D$45)/'0. Parametri'!$D$46
A44: col F | B44: ↳ =0
A45: col G | B45: ↳ =E6*3
A46: col H | B46: ↳ =F6+G6
A47: col I | B47: Risposta RAI #1,2 + assunzione distribuzione
...
